<?xml version="1.0" encoding="UTF-8"?>
<testsuites>
	<testsuite name="TestEndpoint-20200708225605" tests="1" file=".py" time="0.003" timestamp="2020-07-08T22:56:05" failures="1" errors="0" skipped="0">
		<testcase classname="TestEndpoint" name="test_closeEndpoint" time="0.003" timestamp="2020-07-08T22:56:05" file="test_endpoint.py" line="16">
			<failure type="AssertionError" message="Traceback (most recent call last):
  File &quot;./test_endpoint.py&quot;, line 21, in test_closeEndpoint
    endpoint.closeAllEndpoint()
  File &quot;/home/tuimac/github/tagdns/tagdns/endpoint.py&quot;, line 42, in closeAllEndpoint
    self.outbound.closeEndpoint()
AttributeError: 'NoneType' object has no attribute 'closeEndpoint'
"><![CDATA[Traceback (most recent call last):
  File "./test_endpoint.py", line 21, in test_closeEndpoint
    endpoint.closeAllEndpoint()
AttributeError: 'NoneType' object has no attribute 'closeEndpoint'

During handling of the above exception, another exception occurred:

Traceback (most recent call last):
  File "./test_endpoint.py", line 25, in test_closeEndpoint
    self.fail(traceback.format_exc())
AssertionError: Traceback (most recent call last):
  File "./test_endpoint.py", line 21, in test_closeEndpoint
    endpoint.closeAllEndpoint()
  File "/home/tuimac/github/tagdns/tagdns/endpoint.py", line 42, in closeAllEndpoint
    self.outbound.closeEndpoint()
AttributeError: 'NoneType' object has no attribute 'closeEndpoint'

]]></failure>
			<system-out><![CDATA[hello
]]></system-out>
			<system-err><![CDATA[Exception in thread Thread-2:
]]></system-err>
		</testcase>
	</testsuite>
</testsuites>
